Traceback (most recent call last):
  File "C:\project\project\machine_learning\network\model.py", line 97, in <module>
    model.train(train_x, validate_x, train_y, validate_y, 1)
  File "C:\project\project\machine_learning\network\model.py", line 68, in train
    history = self.model.fit(
              ^^^^^^^^^^^^^^^
  File "C:\Users\ninjamonkey\AppData\Local\Programs\Python\Python311\Lib\site-packages\keras\src\utils\traceback_utils.py", line 70, in error_handler
    raise e.with_traceback(filtered_tb) from None
  File "C:\Users\NINJAM~1\AppData\Local\Temp\__autograph_generated_filec9_sth43.py", line 15, in tf__train_function
    retval_ = ag__.converted_call(ag__.ld(step_function), (ag__.ld(self), ag__.ld(iterator)), None, fscope)
    ^^^^^
ValueError: in user code:

    File "C:\Users\ninjamonkey\AppData\Local\Programs\Python\Python311\Lib\site-packages\keras\src\engine\training.py", line 1377, in train_function  *
        return step_function(self, iterator)
    File "C:\Users\ninjamonkey\AppData\Local\Programs\Python\Python311\Lib\site-packages\keras\src\engine\training.py", line 1360, in step_function  **
        outputs = model.distribute_strategy.run(run_step, args=(data,))
    File "C:\Users\ninjamonkey\AppData\Local\Programs\Python\Python311\Lib\site-packages\keras\src\engine\training.py", line 1349, in run_step  **
        outputs = model.train_step(data)
    File "C:\Users\ninjamonkey\AppData\Local\Programs\Python\Python311\Lib\site-packages\keras\src\engine\training.py", line 1126, in train_step
        y_pred = self(x, training=True)
    File "C:\Users\ninjamonkey\AppData\Local\Programs\Python\Python311\Lib\site-packages\keras\src\utils\traceback_utils.py", line 70, in error_handler
        raise e.with_traceback(filtered_tb) from None
    File "C:\Users\ninjamonkey\AppData\Local\Programs\Python\Python311\Lib\site-packages\keras\src\engine\input_spec.py", line 253, in assert_input_compatibility
        raise ValueError(

    ValueError: Exception encountered when calling layer 'sequential' (type Sequential).

    Input 0 of layer "layer_0" is incompatible with the layer: expected min_ndim=2, found ndim=1. Full shape received: (None,)

    Call arguments received by layer 'sequential' (type Sequential):
      • inputs=tf.Tensor(shape=(None,), dtype=int32)
      • training=True
      • mask=None